<?xml version="1.0" ?>
<!-- =================================================================================== -->
<!-- |    This document was autogenerated by xacro from /home/mayankm/boeing-abhyast/phase_vii_ws/src/Phase-VII/simulation_module/alpha_description/robots/alpha_bot.urdf.xacro | -->
<!-- |    EDITING THIS FILE BY HAND IS NOT RECOMMENDED                                 | -->
<!-- =================================================================================== -->
<robot name="alpha" xmlns:controller="http://playerstage.sourceforge.net/gazebo/xmlschema/#controller" xmlns:interface="http://ros.org/wiki/xacro" xmlns:sensor="http://playerstage.sourceforge.net/gazebo/xmlschema/#sensor" xmlns:xacro="http://ros.org/wiki/xacro">
  <material name="Blue">
    <color rgba="0.0 0.0 0.8 1.0"/>
  </material>
  <material name="Green">
    <color rgba="0.0 0.8 0.0 1.0"/>
  </material>
  <material name="Grey">
    <color rgba="0.7 0.7 0.7 1.0"/>
  </material>
  <material name="Grey2">
    <color rgba="0.9 0.9 0.9 1.0"/>
  </material>
  <material name="Red">
    <color rgba="0.8 0.0 0.0 1.0"/>
  </material>
  <material name="White">
    <color rgba="1.0 1.0 1.0 1.0"/>
  </material>
  <material name="Black">
    <color rgba="0.1 0.1 0.1 1.0"/>
  </material>
  <material name="LightGrey">
    <color rgba="0.6 0.6 0.6 1.0"/>
  </material>
  <!-- DATA SOURCES -->
  <!-- all link geometry sizes are obtained from Function provided CAD model unless stated otherwise -->
  <!-- all simplified collision geometry are hand approximated from CAD model, sometimes from respective bounding boxes -->
  <link name="base_link">
    <inertial>
      <mass value="8.5"/>
      <origin rpy="0 0 0" xyz="0 0 0"/>
      <inertia ixx="0.016994" ixy="1.2142E-05" ixz="-1.5304E-05" iyy="0.015814" iyz="0.00078225" izz="0.022766"/>
    </inertial>
    <visual>
      <origin rpy="1.57079632679 0 0" xyz="0 0 -0.031"/>
      <geometry>
        <mesh filename="package://alpha_description/meshes/chassis/base_plate.STL"/>
      </geometry>
      <material name="White"/>
    </visual>
    <collision>
      <origin rpy="0 0 0" xyz="0 0 0.05469"/>
      <geometry>
        <cylinder length="0.10938" radius="0.19"/>
      </geometry>
    </collision>
  </link>
  <!-- base_footprint is a fictitious link(frame) that is on the ground right below base_link origin,
         navigation stack dedpends on this frame -->
  <link name="base_footprint">
    <visual>
      <origin rpy="0 0 0" xyz="0 0 0"/>
      <geometry>
        <box size="0.01 0.01 0.01"/>
      </geometry>
      <material name="White"/>
    </visual>
  </link>
  <joint name="base_footprint_joint" type="fixed">
    <origin rpy="0 0 -1.57079632679" xyz="0 0 0.0365"/>
    <parent link="base_footprint"/>
    <child link="base_link"/>
    <axis xyz="0 0 0"/>
  </joint>
  <joint name="fl_rotation_joint" type="fixed">
    <origin rpy="1.57079632679 0 3.14159265359" xyz="0.0 0.11 0.0"/>
    <parent link="base_link"/>
    <child link="fl_rotation_link"/>
  </joint>
  <link name="fl_rotation_link">
    <inertial>
      <mass value="0.2"/>
      <origin rpy="0 0 0" xyz="0 0 0"/>
      <inertia ixx="7.34836188095286E-07" ixy="-8.85813875476203E-23" ixz="-2.27179291546233E-23" iyy="5.26473063708137E-07" iyz="-1.32876082683251E-22" izz="7.34836188095287E-07"/>
    </inertial>
    <visual>
      <origin rpy="0 0 0" xyz="0 0 0"/>
      <geometry>
        <mesh filename="package://alpha_description/meshes/chassis/caster_body.STL"/>
      </geometry>
      <material name="Black"/>
    </visual>
    <collision>
      <origin rpy="0 0 0" xyz="0 0 0"/>
      <geometry>
        <mesh filename="package://alpha_description/meshes/chassis/caster_body.STL"/>
      </geometry>
    </collision>
  </link>
  <link name="fl_caster_link">
    <inertial>
      <origin rpy="0 0 0" xyz="0 0 0"/>
      <mass value="0.0005236"/>
      <inertia ixx="5.236E-09" ixy="1.551E-25" ixz="1.034E-25" iyy="5.236E-09" iyz="6.2039E-25" izz="5.236E-09"/>
    </inertial>
    <visual>
      <origin rpy="0 0 0" xyz="0 0 0"/>
      <geometry>
        <mesh filename="package://alpha_description/meshes/chassis/caster_ball.STL"/>
      </geometry>
    </visual>
    <collision>
      <origin rpy="0 0 0" xyz="0 0 0"/>
      <geometry>
        <mesh filename="package://alpha_description/meshes/chassis/caster_ball.STL"/>
      </geometry>
    </collision>
  </link>
  <joint name="fl_caster_joint" type="fixed">
    <origin rpy="0 0 0" xyz="0 -0.026 0"/>
    <parent link="fl_rotation_link"/>
    <child link="fl_caster_link"/>
    <axis xyz="0 0 0"/>
  </joint>
  <transmission name="fl_rotation_trans" type="alpha_mechanism_model/SimpleTransmission">
    <actuator name="fl_rotation_caster">
      <mechanicalReduction>1</mechanicalReduction>
    </actuator>
    <joint name="fl_caster_joint">
      <hardwareInterface>EffortJointInterface</hardwareInterface>
    </joint>
  </transmission>
  <joint name="fl_left_wheel_joint" type="continuous">
    <axis xyz="0 0 -1"/>
    <limit effort="18" velocity="1.5"/>
    <safety_controller k_velocity="1"/>
    <dynamics damping="1.0" friction="0.0"/>
    <origin rpy="1.57079632679 0 -1.57079632679" xyz="0.132 0.022 -0.165"/>
    <parent link="fl_rotation_link"/>
    <child link="fl_left_wheel_link"/>
  </joint>
  <link name="fl_left_wheel_link">
    <inertial>
      <mass value="1.0"/>
      <origin xyz="0 0 0"/>
      <inertia ixx="0.00027992" ixy="-1.1223E-19" ixz="2.6988E-20" iyy="0.00027992" iyz="8.6881E-21" izz="0.00045332"/>
    </inertial>
    <visual>
      <origin rpy="0 0 0" xyz="0 0 0"/>
      <geometry>
        <mesh filename="package://alpha_description/meshes/chassis/wheel.STL"/>
      </geometry>
      <material name="Black"/>
    </visual>
    <collision>
      <origin rpy="0 0 0" xyz="0 0 0"/>
      <!-- rotation because cyl. geom primitive has symmetry axis in +x direction -->
      <geometry>
        <mesh filename="package://alpha_description/meshes/chassis/wheel.STL"/>
      </geometry>
    </collision>
  </link>
  <gazebo reference="fl_left_wheel_link">
    <mu1 value="1.0"/>
    <mu2 value="1.0"/>
    <kp value="1000000.0"/>
    <kd value="100.0"/>
    <maxVel value="1.0"/>
    <minDepth value="0.0"/>
    <material>Gazebo/Black</material>
  </gazebo>
  <transmission name="fl_left_wheel_trans" type="alpha_mechanism_model/SimpleTransmission">
    <actuator name="fl_left_wheel_motor"/>
    <joint name="fl_left_wheel_joint"/>
    <mechanicalReduction>-1</mechanicalReduction>
  </transmission>
  <joint name="fl_right_wheel_joint" type="continuous">
    <axis xyz="0 0 1"/>
    <limit effort="18" velocity="1.5"/>
    <safety_controller k_velocity="1"/>
    <dynamics damping="1.0" friction="0.0"/>
    <origin rpy="1.57079632679 0 1.57079632679" xyz="-0.132 0.022 -0.165"/>
    <parent link="fl_rotation_link"/>
    <child link="fl_right_wheel_link"/>
  </joint>
  <link name="fl_right_wheel_link">
    <inertial>
      <mass value="1.0"/>
      <origin xyz="0 0 0"/>
      <inertia ixx="0.00027992" ixy="-1.1223E-19" ixz="2.6988E-20" iyy="0.00027992" iyz="8.6881E-21" izz="0.00045332"/>
    </inertial>
    <visual>
      <origin rpy="0 0 0" xyz="0 0 0"/>
      <geometry>
        <mesh filename="package://alpha_description/meshes/chassis/wheel.STL"/>
      </geometry>
      <material name="Black"/>
    </visual>
    <collision>
      <origin rpy="0 0 0" xyz="0 0 0"/>
      <!-- rotation because cyl. geom primitive has symmetry axis in +x direction -->
      <geometry>
        <mesh filename="package://alpha_description/meshes/chassis/wheel.STL"/>
      </geometry>
    </collision>
  </link>
  <gazebo reference="fl_right_wheel_link">
    <mu1 value="1.0"/>
    <mu2 value="1.0"/>
    <kp value="1000000.0"/>
    <kd value="100.0"/>
    <maxVel value="1.0"/>
    <minDepth value="0.0"/>
    <material>Gazebo/Black</material>
  </gazebo>
  <transmission name="fl_right_wheel_trans" type="alpha_mechanism_model/SimpleTransmission">
    <actuator name="fl_right_wheel_motor"/>
    <joint name="fl_right_wheel_joint"/>
    <mechanicalReduction>1</mechanicalReduction>
  </transmission>
  <gazebo reference="fl_caster_link">
    <mu1 value="0.2"/>
    <mu2 value="0.2"/>
    <kp value="1000000.0"/>
    <kd value="100.0"/>
    <maxVel value="1.0"/>
    <minDepth value="0.0"/>
    <material>Gazebo/Black</material>
  </gazebo>
  <gazebo reference="base_link">
    <material>Gazebo/Grey</material>
    <plugin filename="libgazebo_ros_p3d.so" name="p3d_base_controller">
      <alwaysOn>true</alwaysOn>
      <updateRate>100.0</updateRate>
      <bodyName>base_link</bodyName>
      <topicName>base_pose_ground_truth</topicName>
      <gaussianNoise>0.01</gaussianNoise>
      <frameName>map</frameName>
      <xyzOffsets>0 0 0</xyzOffsets>
      <rpyOffsets>0 0 0</rpyOffsets>
    </plugin>
  </gazebo>
  <gazebo>
    <plugin filename="libgazebo_ros_diff_drive.so" name="differential_drive_controller">
      <robotNamespace>/</robotNamespace>
      <alwaysOn>true</alwaysOn>
      <updateRate>100.0</updateRate>
      <leftJoint>fl_left_wheel_joint</leftJoint>
      <rightJoint>fl_right_wheel_joint</rightJoint>
      <wheelSeparation>0.308</wheelSeparation>
      <wheelDiameter>0.106</wheelDiameter>
      <wheelTorque>20</wheelTorque>
      <wheelAcceleration>0</wheelAcceleration>
      <commandTopic>cmd_vel</commandTopic>
      <odometryTopic>odom</odometryTopic>
      <odometryFrame>odom</odometryFrame>
      <robotBaseFrame>base_footprint</robotBaseFrame>
      <legacyMode>true</legacyMode>
      <publishWheelTF>false</publishWheelTF>
      <publishWheelJointState>true</publishWheelJointState>
      <publishTf>1</publishTf>
    </plugin>
  </gazebo>
  <joint name="kinect_frame_joint" type="fixed">
    <origin rpy="0 0 1.57079632679" xyz="0 0.125 0.215"/>
    <parent link="base_link"/>
    <child link="kinect_frame"/>
  </joint>
  <link name="kinect_frame">
    <inertial>
      <mass value="1.4"/>
      <origin rpy="0 0 0" xyz="0 0 0"/>
      <inertia ixx="0.01" ixy="0.0" ixz="0.0" iyy="0.01" iyz="0.0" izz="0.01"/>
    </inertial>
    <visual>
      <origin rpy="0 0 0" xyz="0.0 0.012 0"/>
      <geometry>
        <mesh filename="package://alpha_description/meshes/sensors/kinect/v2/kinect.dae" scale="0.001 0.001 0.001"/>
      </geometry>
    </visual>
    <collision>
      <origin rpy="0 0 0" xyz="0.0 0.012 0"/>
      <geometry>
        <mesh filename="package://alpha_description/meshes/sensors/kinect/v2/kinect.dae" scale="0.001 0.001 0.001"/>
      </geometry>
    </collision>
  </link>
  <joint name="kinect_optical_joint" type="fixed">
    <origin rpy="-1.57079632679 0.0 -1.57079632679" xyz="0.0 0.0 0.0"/>
    <parent link="kinect_frame"/>
    <child link="kinect_optical_frame"/>
  </joint>
  <link name="kinect_optical_frame"/>
  <gazebo reference="kinect_frame">
    <sensor name="kinect_frame_sensor" type="depth">
      <always_on>true</always_on>
      <update_rate>20.0</update_rate>
      <camera>
        <horizontal_fov>0.994837673637</horizontal_fov>
        <image>
          <format>R8G8B8</format>
          <width>1280</width>
          <height>720</height>
        </image>
        <clip>
          <near>0.01</near>
          <far>5</far>
        </clip>
      </camera>
      <plugin filename="libgazebo_ros_openni_kinect.so" name="kinect_frame_controller">
        <robotNamespace>/</robotNamespace>
        <alwaysOn>true</alwaysOn>
        <updateRate>20.0</updateRate>
        <cameraName>kinect</cameraName>
        <imageTopicName>kinect/ir/image_raw</imageTopicName>
        <cameraInfoTopicName>kinect/ir/camera_info</cameraInfoTopicName>
        <depthImageTopicName>kinect/depth/image_raw</depthImageTopicName>
        <depthImageCameraInfoTopicName>kinect/depth/camera_info</depthImageCameraInfoTopicName>
        <pointCloudTopicName>kinect/depth/points</pointCloudTopicName>
        <frameName>kinect_optical_frame</frameName>
        <pointCloudCutoff>0.5</pointCloudCutoff>
        <distortionK1>0.00000001</distortionK1>
        <distortionK2>0.00000001</distortionK2>
        <distortionK3>0.00000001</distortionK3>
        <distortionT1>0.00000001</distortionT1>
        <distortionT2>0.00000001</distortionT2>
        <CxPrime>0</CxPrime>
        <Cx>0</Cx>
        <Cy>0</Cy>
        <focalLength>0</focalLength>
        <hackBaseline>0</hackBaseline>
      </plugin>
    </sensor>
  </gazebo>
  <joint name="hokuyo_joint" type="fixed">
    <axis xyz="0 1 0"/>
    <origin rpy="0 0 1.57079632679" xyz="0 0 0.32"/>
    <parent link="base_link"/>
    <child link="hokuyo_frame"/>
  </joint>
  <link name="hokuyo_frame">
    <inertial>
      <mass value="0.270"/>
      <origin rpy="0 0 0" xyz="0 0 0"/>
      <inertia ixx="2.632e-4" ixy="0" ixz="0" iyy="2.632e-4" iyz="0" izz="1.62e-4"/>
    </inertial>
    <visual>
      <origin rpy="0 0 0" xyz="0 0 0"/>
      <geometry>
        <mesh filename="package://alpha_description/meshes/sensors/hokuyo_laser/hokuyo_utm_30lx.dae"/>
      </geometry>
    </visual>
    <collision>
      <origin rpy="0 0 0" xyz="0 0 -0.0115"/>
      <geometry>
        <box size="0.058 0.058 0.087"/>
      </geometry>
    </collision>
  </link>
  <gazebo reference="hokuyo_frame">
    <sensor name="hokuyo" type="ray">
      <always_on>true</always_on>
      <update_rate>40</update_rate>
      <pose>0 0 0 0 0 0</pose>
      <visualize>false</visualize>
      <ray>
        <scan>
          <horizontal>
            <samples>640</samples>
            <resolution>1</resolution>
            <min_angle>-1.3962634</min_angle>
            <max_angle>1.3962634</max_angle>
          </horizontal>
        </scan>
        <range>
          <min>0.08</min>
          <max>10.0</max>
          <resolution>0.01</resolution>
        </range>
        <noise>
          <type>gaussian</type>
          <!-- Noise parameters based on published spec for Hokuyo laser
                 achieving "+-30mm" accuracy at range < 10m.  A mean of 0.0m and
                 stddev of 0.01m will put 99.7% of samples within 0.03m of the true
                 reading. -->
          <mean>0.0</mean>
          <stddev>0.01</stddev>
        </noise>
      </ray>
      <plugin filename="libgazebo_ros_laser.so" name="gazebo_ros_hokuyo_controller">
        <robotNamespace>/</robotNamespace>
        <gaussianNoise>0.005</gaussianNoise>
        <alwaysOn>true</alwaysOn>
        <updateRate>40</updateRate>
        <topicName>base_scan</topicName>
        <frameName>hokuyo_frame</frameName>
        <hokuyoMinIntensity>101</hokuyoMinIntensity>
      </plugin>
    </sensor>
  </gazebo>
</robot>
