<?xml version="1.0" ?>
<!-- =================================================================================== -->
<!-- |    This document was autogenerated by xacro from /home/mayankm/boeing-abhyast/phase_vii_ws/src/Phase-VII/alpha_description/robots/alpha_bot.urdf.xacro | -->
<!-- |    EDITING THIS FILE BY HAND IS NOT RECOMMENDED                                 | -->
<!-- =================================================================================== -->
<robot name="alpha" xmlns:controller="http://playerstage.sourceforge.net/gazebo/xmlschema/#controller" xmlns:interface="http://ros.org/wiki/xacro" xmlns:sensor="http://playerstage.sourceforge.net/gazebo/xmlschema/#sensor" xmlns:xacro="http://ros.org/wiki/xacro">
  <!-- DATA SOURCES -->
  <!-- all link geometry sizes are obtained from Function provided CAD model unless stated otherwise -->
  <!-- all simplified collision geometry are hand approximated from CAD model, sometimes from respective bounding boxes -->
  <link name="base_link">
    <inertial>
      <mass value="2.4"/>
      <origin xyz="0.001 0.0 -0.034"/>
      <inertia ixx="0.019995" ixy="0.0" ixz="0.0" iyy="0.019995" iyz="0.0" izz="0.03675"/>
    </inertial>
    <visual>
      <origin rpy="0 0 0" xyz="0 0 0"/>
      <geometry>
        <mesh filename="package://alpha_description/meshes/chassis/base_plate.dae"/>
      </geometry>
      <material name="White"/>
    </visual>
    <collision>
      <origin rpy="0 0 0" xyz="0 0 0"/>
      <geometry>
        <cylinder length="0.10938" radius="0.178"/>
      </geometry>
    </collision>
  </link>
  <!-- base_footprint is a fictitious link(frame) that is on the ground right below base_link origin,
         navigation stack dedpends on this frame -->
  <link name="base_footprint">
    <inertial>
      <mass value="1.0"/>
      <origin xyz="0 0 0"/>
      <inertia ixx="0.019995" ixy="0.0" ixz="0.0" iyy="0.019995" iyz="0.0" izz="0.03675"/>
    </inertial>
    <visual>
      <origin rpy="0 0 0" xyz="0 0 0"/>
      <geometry>
        <box size="0.01 0.01 0.01"/>
      </geometry>
      <material name="White"/>
    </visual>
    <collision>
      <!-- represent base collision with a simple rectangular model, positioned by base_size_z s.t. top
             surface of the collision box matches the top surface of the alpha base -->
      <origin rpy="0 0 0" xyz="0 0 0.080745"/>
      <geometry>
        <box size="0.001 0.001 0.001"/>
      </geometry>
    </collision>
  </link>
  <joint name="base_footprint_joint" type="fixed">
    <origin rpy="0 0 0" xyz="0 0 0.051"/>
    <child link="base_link"/>
    <parent link="base_footprint"/>
  </joint>
  <joint name="fl_caster_rotation_joint" type="continuous">
    <axis xyz="0 0 1"/>
    <origin rpy="-1.57079632679 0 0" xyz="0.115 0 0.007"/>
    <limit effort="18" velocity="1.5"/>
    <safety_controller k_velocity="1"/>
    <calibration rising="-0.785398163397"/>
    <dynamics damping="1.0" friction="0.0"/>
    <origin rpy="0 0 0" xyz="0.115 0.0 0.007"/>
    <parent link="base_link"/>
    <child link="fl_caster_rotation_link"/>
  </joint>
  <link name="fl_caster_rotation_link">
    <inertial>
      <mass value="0.01"/>
      <origin xyz="0 0 0"/>
      <inertia ixx="0.001" ixy="0.0" ixz="0.0" iyy="0.001" iyz="0.0" izz="0.001"/>
    </inertial>
    <visual>
      <origin rpy="0 0 0" xyz="0 0 0"/>
      <geometry>
        <mesh filename="package://alpha_description/meshes/chassis/caster.stl"/>
      </geometry>
      <material name="Caster"/>
    </visual>
    <collision>
      <origin rpy="0 0 0" xyz="0 0 0"/>
      <geometry>
        <mesh filename="package://alpha_description/meshes/chassis/caster_L.stl"/>
      </geometry>
    </collision>
  </link>
  <transmission name="fl_caster_rotation_trans" type="alpha_mechanism_model/SimpleTransmission">
    <actuator name="fl_caster_rotation_motor">
      <mechanicalReduction>-79.2380952381</mechanicalReduction>
    </actuator>
    <joint name="fl_caster_rotation_joint">
      <hardwareInterface>EffortJointInterface</hardwareInterface>
    </joint>
  </transmission>
  <joint name="fl_caster_l_wheel_joint" type="continuous">
    <axis xyz="0 0 1"/>
    <limit effort="18" velocity="1.5"/>
    <safety_controller k_velocity="1"/>
    <dynamics damping="1.0" friction="0.0"/>
    <origin rpy="-1.57079632679 0 0" xyz="0 0.28 0.026"/>
    <parent link="fl_caster_rotation_link"/>
    <child link="fl_caster_l_wheel_link"/>
  </joint>
  <link name="fl_caster_l_wheel_link">
    <inertial>
      <mass value="0.01"/>
      <origin xyz="0 0 0"/>
      <inertia ixx="0.001" ixy="0.0" ixz="0.0" iyy="0.001" iyz="0.0" izz="0.001"/>
    </inertial>
    <visual>
      <origin rpy="0 0 0" xyz="0 0 0"/>
      <geometry>
        <mesh filename="package://alpha_description/meshes/chassis/wheel.dae"/>
      </geometry>
      <material name="Wheel_l"/>
    </visual>
    <collision>
      <origin rpy="1.57079632679 0 0" xyz="0 0 0"/>
      <!-- rotation because cyl. geom primitive has symmetry axis in +x direction -->
      <geometry>
        <cylinder length="0.0206" radius="0.035"/>
      </geometry>
    </collision>
  </link>
  <gazebo reference="fl_caster_l_wheel_link">
    <mu1 value="1.0"/>
    <mu2 value="1.0"/>
    <kp value="1000000.0"/>
    <kd value="100.0"/>
    <maxVel value="1.0"/>
    <minDepth value="0.001"/>
  </gazebo>
  <transmission name="fl_caster_l_wheel_trans" type="alpha_mechanism_model/SimpleTransmission">
    <actuator name="fl_caster_l_wheel_motor"/>
    <joint name="fl_caster_l_wheel_joint"/>
    <mechanicalReduction>79.2380952381</mechanicalReduction>
  </transmission>
  <joint name="fl_caster_r_wheel_joint" type="continuous">
    <axis xyz="0 0 1"/>
    <limit effort="18" velocity="1.5"/>
    <safety_controller k_velocity="1"/>
    <dynamics damping="1.0" friction="0.0"/>
    <origin rpy="-1.57079632679 0 0" xyz="0 -0.28 0.026"/>
    <parent link="fl_caster_rotation_link"/>
    <child link="fl_caster_r_wheel_link"/>
  </joint>
  <link name="fl_caster_r_wheel_link">
    <inertial>
      <mass value="0.01"/>
      <origin xyz="0 0 0"/>
      <inertia ixx="0.001" ixy="0.0" ixz="0.0" iyy="0.001" iyz="0.0" izz="0.001"/>
    </inertial>
    <visual>
      <origin rpy="0 0 0" xyz="0 0 0"/>
      <geometry>
        <mesh filename="package://alpha_description/meshes/chassis/wheel.dae"/>
      </geometry>
      <material name="Wheel_r"/>
    </visual>
    <collision>
      <origin rpy="1.57079632679 0 0" xyz="0 0 0"/>
      <!-- rotation because cyl. geom primitive has symmetry axis in +x direction -->
      <geometry>
        <cylinder length="0.0206" radius="0.035"/>
      </geometry>
    </collision>
  </link>
  <gazebo reference="fl_caster_r_wheel_link">
    <mu1 value="1.0"/>
    <mu2 value="1.0"/>
    <kp value="1000000.0"/>
    <kd value="100.0"/>
    <maxVel value="1.0"/>
    <minDepth value="0.001"/>
  </gazebo>
  <transmission name="fl_caster_r_wheel_trans" type="alpha_mechanism_model/SimpleTransmission">
    <actuator name="fl_caster_r_wheel_motor"/>
    <joint name="fl_caster_r_wheel_joint"/>
    <mechanicalReduction>-79.2380952381</mechanicalReduction>
  </transmission>
  <gazebo reference="fl_caster_rotation_link">
    <mu1 value="0.0"/>
    <mu2 value="0.0"/>
    <kp value="1000000.0"/>
    <kd value="100.0"/>
    <minDepth value="0.001"/>
    <maxVel value="1.0"/>
  </gazebo>
  <gazebo reference="base_link">
    <plugin filename="libgazebo_ros_p3d.so" name="p3d_base_controller">
      <alwaysOn>true</alwaysOn>
      <updateRate>100.0</updateRate>
      <bodyName>base_link</bodyName>
      <topicName>base_pose_ground_truth</topicName>
      <gaussianNoise>0.01</gaussianNoise>
      <frameName>map</frameName>
      <xyzOffsets>0 0 0</xyzOffsets>
      <rpyOffsets>0 0 0</rpyOffsets>
    </plugin>
  </gazebo>
</robot>
